[2018-04-11 10:32:42]----TraceErr----
Traceback (most recent call last):
  File "C:\Python36\lib\site-packages\aiohttp\connector.py", line 800, in _wrap_create_connection
    return await self._loop.create_connection(*args, **kwargs)
  File "C:\Python36\lib\asyncio\base_events.py", line 777, in create_connection
    raise exceptions[0]
  File "C:\Python36\lib\asyncio\base_events.py", line 764, in create_connection
    yield from self.sock_connect(sock, address)
  File "C:\Python36\lib\asyncio\selector_events.py", line 450, in sock_connect
    return (yield from fut)
  File "C:\Python36\lib\asyncio\selector_events.py", line 480, in _sock_connect_cb
    raise OSError(err, 'Connect call failed %s' % (address,))
TimeoutError: [Errno 10060] Connect call failed ('172.247.250.35', 80)

The above exception was the direct cause of the following exception:

Traceback (most recent call last):
  File "E:\mygithub\WebCrawler\pubcode\pubcrawler.py", line 100, in Start
    self.m_Loop.run_until_complete(self.Run())
  File "C:\Python36\lib\asyncio\base_events.py", line 467, in run_until_complete
    return future.result()
  File "E:\mygithub\WebCrawler\pubcode\pubcrawler.py", line 164, in Run
    htmls = [f.result() for f in finished]
  File "E:\mygithub\WebCrawler\pubcode\pubcrawler.py", line 164, in <listcomp>
    htmls = [f.result() for f in finished]
  File "E:\mygithub\WebCrawler\pubcode\pubcrawler.py", line 171, in Crawl
    r = await self.m_Session.get(url, headers=self.m_headers)
  File "C:\Python36\lib\site-packages\aiohttp\client.py", line 320, in _request
    traces=traces
  File "C:\Python36\lib\site-packages\aiohttp\connector.py", line 418, in connect
    traces=traces
  File "C:\Python36\lib\site-packages\aiohttp\connector.py", line 736, in _create_connection
    traces=traces
  File "C:\Python36\lib\site-packages\aiohttp\connector.py", line 855, in _create_direct_connection
    raise last_exc
  File "C:\Python36\lib\site-packages\aiohttp\connector.py", line 838, in _create_direct_connection
    req=req, client_error=client_error)
  File "C:\Python36\lib\site-packages\aiohttp\connector.py", line 807, in _wrap_create_connection
    raise client_error(req.connection_key, exc) from exc
aiohttp.client_exceptions.ClientConnectorError: Cannot connect to host www.35zww.com:80 ssl:False [Connect call failed ('172.247.250.35', 80)]

----TraceInfo----
{'kwargs': {'ssl': None, 'family': <AddressFamily.AF_INET: 2>, 'proto': 0, 'flags': <AddressInfo.AI_NUMERICHOST: 4>, 'server_hostname': None, 'local_addr': None}, 'args': (functools.partial(<class 'aiohttp.client_proto.ResponseHandler'>, loop=<_WindowsSelectorEventLoop running=False closed=False debug=False>), '172.247.250.35', 80), 'client_error': <class 'aiohttp.client_exceptions.ClientConnectorError'>, 'req': <aiohttp.client_reqrep.ClientRequest object at 0x00000181396927F0>, 'self': <aiohttp.connector.TCPConnector object at 0x00000181539C5668>}
----extra----
Cannot connect to host www.35zww.com:80 ssl:False [Connect call failed ('172.247.250.35', 80)]

[2018-04-11 11:52:46]----TraceErr----
Traceback (most recent call last):
  File "E:\mygithub\WebCrawler\pubcode\pubcrawler.py", line 104, in Start
    self.m_Loop.run_until_complete(self.Run())
  File "C:\Python36\lib\asyncio\base_events.py", line 467, in run_until_complete
    return future.result()
  File "E:\mygithub\WebCrawler\pubcode\pubcrawler.py", line 168, in Run
    htmls = [f.result() for f in finished]
  File "E:\mygithub\WebCrawler\pubcode\pubcrawler.py", line 168, in <listcomp>
    htmls = [f.result() for f in finished]
  File "E:\mygithub\WebCrawler\pubcode\pubcrawler.py", line 177, in Crawl
    r = await self.m_Session.get(url, headers=self.m_Headers)
  File "C:\Python36\lib\site-packages\aiohttp\client.py", line 331, in _request
    resp = await req.send(conn)
  File "C:\Python36\lib\site-packages\aiohttp\client_reqrep.py", line 524, in send
    await writer.write_headers(status_line, self.headers)
  File "C:\Python36\lib\site-packages\aiohttp\http_writer.py", line 100, in write_headers
    [k + SEP + v + END for k, v in headers.items()])
  File "C:\Python36\lib\site-packages\aiohttp\http_writer.py", line 100, in <listcomp>
    [k + SEP + v + END for k, v in headers.items()])
TypeError: must be str, not int

----TraceInfo----
{'v': 1, 'k': 'Upgrade-Insecure-Requests', '.0': <multidict._multidict._ItemsIter object at 0x000001FB3987C188>, 'SEP': ': ', 'END': '\r\n'}
----extra----
must be str, not int

[2018-04-11 11:57:06]----TraceErr----
Traceback (most recent call last):
  File "C:\Python36\lib\site-packages\aiohttp\connector.py", line 800, in _wrap_create_connection
    return await self._loop.create_connection(*args, **kwargs)
  File "C:\Python36\lib\asyncio\base_events.py", line 777, in create_connection
    raise exceptions[0]
  File "C:\Python36\lib\asyncio\base_events.py", line 764, in create_connection
    yield from self.sock_connect(sock, address)
  File "C:\Python36\lib\asyncio\selector_events.py", line 450, in sock_connect
    return (yield from fut)
  File "C:\Python36\lib\asyncio\selector_events.py", line 480, in _sock_connect_cb
    raise OSError(err, 'Connect call failed %s' % (address,))
TimeoutError: [Errno 10060] Connect call failed ('172.247.250.35', 80)

The above exception was the direct cause of the following exception:

Traceback (most recent call last):
  File "E:\mygithub\WebCrawler\pubcode\pubcrawler.py", line 104, in Start
    self.m_Loop.run_until_complete(self.Run())
  File "C:\Python36\lib\asyncio\base_events.py", line 467, in run_until_complete
    return future.result()
  File "E:\mygithub\WebCrawler\pubcode\pubcrawler.py", line 168, in Run
    htmls = [f.result() for f in finished]
  File "E:\mygithub\WebCrawler\pubcode\pubcrawler.py", line 168, in <listcomp>
    htmls = [f.result() for f in finished]
  File "E:\mygithub\WebCrawler\pubcode\pubcrawler.py", line 177, in Crawl
    r = await self.m_Session.get(url, headers=self.m_Headers)
  File "C:\Python36\lib\site-packages\aiohttp\client.py", line 320, in _request
    traces=traces
  File "C:\Python36\lib\site-packages\aiohttp\connector.py", line 418, in connect
    traces=traces
  File "C:\Python36\lib\site-packages\aiohttp\connector.py", line 736, in _create_connection
    traces=traces
  File "C:\Python36\lib\site-packages\aiohttp\connector.py", line 855, in _create_direct_connection
    raise last_exc
  File "C:\Python36\lib\site-packages\aiohttp\connector.py", line 838, in _create_direct_connection
    req=req, client_error=client_error)
  File "C:\Python36\lib\site-packages\aiohttp\connector.py", line 807, in _wrap_create_connection
    raise client_error(req.connection_key, exc) from exc
aiohttp.client_exceptions.ClientConnectorError: Cannot connect to host www.35zww.com:80 ssl:False [Connect call failed ('172.247.250.35', 80)]

----TraceInfo----
{'kwargs': {'ssl': None, 'family': <AddressFamily.AF_INET: 2>, 'proto': 0, 'flags': <AddressInfo.AI_NUMERICHOST: 4>, 'server_hostname': None, 'local_addr': None}, 'args': (functools.partial(<class 'aiohttp.client_proto.ResponseHandler'>, loop=<_WindowsSelectorEventLoop running=False closed=False debug=False>), '172.247.250.35', 80), 'client_error': <class 'aiohttp.client_exceptions.ClientConnectorError'>, 'req': <aiohttp.client_reqrep.ClientRequest object at 0x00000218372F8E80>, 'self': <aiohttp.connector.TCPConnector object at 0x000002180EF65C50>}
----extra----
Cannot connect to host www.35zww.com:80 ssl:False [Connect call failed ('172.247.250.35', 80)]

